Workbook

Sheet PARAMETROS
A1: CardioCentro Diagnóstico Integral S.A.S.
A2: PARÁMETROS GENERALES DEL MODELO TDABC
A3: Fecha de actualización: 17/02/2026
A5: PARÁMETROS OPERACIONALES
A6: Parámetro | B6: Valor | C6: Unidad
A7: Horas mensuales por colaborador | B7: 184 | C7: horas
A8: Días hábiles al mes | B8: 22 | C8: días
A9: Porcentaje capacidad práctica | B9: 85 | C9: %
A10: Factor prestacional sector salud | B10: 1.4077 | C10: factor
A11: Prima de servicios | B11: 8.33 | C11: %
A12: Cesantías | B12: 8.33 | C12: %
A13: Intereses cesantías | B13: 1 | C13: %
A14: Vacaciones | B14: 4.17 | C14: %
A15: ARL (Riesgo III - CATEROGI) | B15: 2.436 | C15: %
A16: Salud EPS (empleador) | B16: 0 | C16: %
A17: Pensión (empleador) | B17: 12.5 | C17: %
A18: Caja compensación | B18: 4 | C18: %
... A23: Tasa cambio USD (referencial) | B23: 4100 | C23: COP
A25: NOTA: Empresas del sector salud en Colombia
A26: Las empresas del sector salud están EXONERADAS del pago de parafiscales (ICBF 3% + SENA 2%).
A27: Sin embargo, SÍ pagan EPS (8.5%), Pensión (12%), Caja Compensación (4%) y ARL según riesgo.
A30: DISTRIBUCIÓN DE COSTOS INDIRECTOS
A31: Concepto | B31: Criterio
A32: Servicios generales | B32: Por minutos consumidos
A33: Administración | B33: Por volumen de producción
A34: Infraestructura | B34: Por área utilizada (m²)
A37: SEDES OPERATIVAS
A38: Código | B38: Nombre Sede | C38: Ciudad | D38: Área (m²)
A39: S01 | B39: Sede Norte - Bogotá | C39: Bogotá | D39: 450
A40: S02 | B40: Sede Sur - Medellín | C40: Medellín | D40: 380
A41: S03 | B41: Sede Centro - Cali | C41: Cali | D41: 420

Sheet NOMINA
A1: ESTRUCTURA SALARIAL Y NÓMINA
A3: ID | B3: Grupo Ocupacional | C3: Salario Base Mensual | D3: Factor Prestacional | E3: Costo Total Mensual | F3: Cantidad Personal | G3: Costo Total Grupo | H3: Sede
A4: G001 | B4: Cardiólogo Especialista | C4: 12000000 | D4: =PARAMETROS!$B$10 | E4: =C4*D4 | F4: 6 | G4: =E4*F4 | H4: Sede Norte - Bogotá
A5: G002 | B5: Cardiólogo Especialista | C5: 12000000 | D5: =PARAMETROS!$B$10 | E5: =C5*D5 | F5: 5 | G5: =E5*F5 | H5: Sede Sur - Medellín
A6: G003 | B6: Cardiólogo Especialista | C6: 12000000 | D6: =PARAMETROS!$B$10 | E6: =C6*D6 | F6: 4 | G6: =E6*F6 | H6: Sede Centro - Cali
A7: G004 | B7: Cardiólogo General | C7: 8000000 | D7: =PARAMETROS!$B$10 | E7: =C7*D7 | F7: 3 | G7: =E7*F7 | H7: Sede Norte - Bogotá
A8: G005 | B8: Cardiólogo General | C8: 8000000 | D8: =PARAMETROS!$B$10 | E8: =C8*D8 | F8: 2 | G8: =E8*F8 | H8: Sede Sur - Medellín
A9: G006 | B9: Cardiólogo General | C9: 8000000 | D9: =PARAMETROS!$B$10 | E9: =C9*D9 | F9: 6 | G9: =E9*F9 | H9: Sede Centro - Cali
A10: G007 | B10: Médico General | C10: 5000000 | D10: =PARAMETROS!$B$10 | E10: =C10*D10 | F10: 5 | G10: =E10*F10 | H10: Sede Norte - Bogotá
A11: G008 | B11: Médico General | C11: 5000000 | D11: =PARAMETROS!$B$10 | E11: =C11*D11 | F11: 4 | G11: =E11*F11 | H11: Sede Sur - Medellín
A12: G009 | B12: Médico General | C12: 5000000 | D12: =PARAMETROS!$B$10 | E12: =C12*D12 | F12: 6 | G12: =E12*F12 | H12: Sede Centro - Cali
A13: G010 | B13: Enfermero Especializado | C13: 3500000 | D13: =PARAMETROS!$B$10 | E13: =C13*D13 | F13: 5 | G13: =E13*F13 | H13: Sede Norte - Bogotá
A14: G011 | B14: Enfermero Especializado | C14: 3500000 | D14: =PARAMETROS!$B$10 | E14: =C14*D14 | F14: 2 | G14: =E14*F14 | H14: Sede Sur - Medellín
A15: G012 | B15: Enfermero Especializado | C15: 3500000 | D15: =PARAMETROS!$B$10 | E15: =C15*D15 | F15: 2 | G15: =E15*F15 | H15: Sede Centro - Cali
... A24: G021 | B24: Auxiliar de Enfermería | C24: 1800000 | D24: =PARAMETROS!$B$10 | E24: =C24*D24 | F24: 3 | G24: =E24*F24 | H24: Sede Centro - Cali
B25: TOTAL NÓMINA MENSUAL | G25: =SUM(G4:G24)

Sheet CAPACIDAD
A1: ANÁLISIS DE CAPACIDAD PRÁCTICA
A2: NOTA: La capacidad práctica (85%) es el tiempo REAL disponible. Se descuenta ~15% por pausas, reuniones, capacitación, etc.
A4: Grupo Ocupacional | B4: Horas Mensuales | C4: Minutos Disponibles | D4: % Capacidad Práctica | E4: Minutos Capacidad Práctica | F4: Personal Disponible | G4: Total Minutos Grupo
A5: Cardiólogo Especialista | B5: =PARAMETROS!$B$7 | C5: =B5*60 | D5: =PARAMETROS!$B$9/100 | E5: =C5*D5 | F5: =SUMIF(NOMINA!$B:$B,A5,NOMINA!$F:$F) | G5: =E5*F5
A6: Cardiólogo General | B6: =PARAMETROS!$B$7 | C6: =B6*60 | D6: =PARAMETROS!$B$9/100 | E6: =C6*D6 | F6: =SUMIF(NOMINA!$B:$B,A6,NOMINA!$F:$F) | G6: =E6*F6
A7: Médico General | B7: =PARAMETROS!$B$7 | C7: =B7*60 | D7: =PARAMETROS!$B$9/100 | E7: =C7*D7 | F7: =SUMIF(NOMINA!$B:$B,A7,NOMINA!$F:$F) | G7: =E7*F7
A8: Enfermero Especializado | B8: =PARAMETROS!$B$7 | C8: =B8*60 | D8: =PARAMETROS!$B$9/100 | E8: =C8*D8 | F8: =SUMIF(NOMINA!$B:$B,A8,NOMINA!$F:$F) | G8: =E8*F8
A9: Enfermero | B9: =PARAMETROS!$B$7 | C9: =B9*60 | D9: =PARAMETROS!$B$9/100 | E9: =C9*D9 | F9: =SUMIF(NOMINA!$B:$B,A9,NOMINA!$F:$F) | G9: =E9*F9
A10: Técnico Radiólogo | B10: =PARAMETROS!$B$7 | C10: =B10*60 | D10: =PARAMETROS!$B$9/100 | E10: =C10*D10 | F10: =SUMIF(NOMINA!$B:$B,A10,NOMINA!$F:$F) | G10: =E10*F10
A11: Auxiliar de Enfermería | B11: =PARAMETROS!$B$7 | C11: =B11*60 | D11: =PARAMETROS!$B$9/100 | E11: =C11*D11 | F11: =SUMIF(NOMINA!$B:$B,A11,NOMINA!$F:$F) | G11: =E11*F11
A12: TOTAL CAPACIDAD ORGANIZACIONAL | G12: =SUM(G4:G11)

Sheet COSTO_POR_MINUTO
A1: COSTO POR MINUTO - NÚCLEO DEL MODELO TDABC
A3: Grupo Ocupacional | B3: Costo Total Mensual | C3: Minutos Capacidad Práctica | D3: Costo por Minuto | E3: Sede
A4: Cardiólogo Especialista | B4: =SUMIFS(NOMINA!$E:$E,NOMINA!$B:$B,A4,NOMINA!$H:$H,E4) | C4: =VLOOKUP(A4,CAPACIDAD!$A:$E,5,FALSE) | D4: =IF(C4>0,B4/C4,0) | E4: Sede Norte - Bogotá
A5: Cardiólogo Especialista | B5: =SUMIFS(NOMINA!$E:$E,NOMINA!$B:$B,A5,NOMINA!$H:$H,E5) | C5: =VLOOKUP(A5,CAPACIDAD!$A:$E,5,FALSE) | D5: =IF(C5>0,B5/C5,0) | E5: Sede Sur - Medellín
A6: Cardiólogo Especialista | B6: =SUMIFS(NOMINA!$E:$E,NOMINA!$B:$B,A6,NOMINA!$H:$H,E6) | C6: =VLOOKUP(A6,CAPACIDAD!$A:$E,5,FALSE) | D6: =IF(C6>0,B6/C6,0) | E6: Sede Centro - Cali
A7: Cardiólogo General | B7: =SUMIFS(NOMINA!$E:$E,NOMINA!$B:$B,A7,NOMINA!$H:$H,E7) | C7: =VLOOKUP(A7,CAPACIDAD!$A:$E,5,FALSE) | D7: =IF(C7>0,B7/C7,0) | E7: Sede Norte - Bogotá
A8: Cardiólogo General | B8: =SUMIFS(NOMINA!$E:$E,NOMINA!$B:$B,A8,NOMINA!$H:$H,E8) | C8: =VLOOKUP(A8,CAPACIDAD!$A:$E,5,FALSE) | D8: =IF(C8>0,B8/C8,0) | E8: Sede Sur - Medellín
A9: Cardiólogo General | B9: =SUMIFS(NOMINA!$E:$E,NOMINA!$B:$B,A9,NOMINA!$H:$H,E9) | C9: =VLOOKUP(A9,CAPACIDAD!$A:$E,5,FALSE) | D9: =IF(C9>0,B9/C9,0) | E9: Sede Centro - Cali
A10: Médico General | B10: =SUMIFS(NOMINA!$E:$E,NOMINA!$B:$B,A10,NOMINA!$H:$H,E10) | C10: =VLOOKUP(A10,CAPACIDAD!$A:$E,5,FALSE) | D10: =IF(C10>0,B10/C10,0) | E10: Sede Norte - Bogotá
A11: Médico General | B11: =SUMIFS(NOMINA!$E:$E,NOMINA!$B:$B,A11,NOMINA!$H:$H,E11) | C11: =VLOOKUP(A11,CAPACIDAD!$A:$E,5,FALSE) | D11: =IF(C11>0,B11/C11,0) | E11: Sede Sur - Medellín
A12: Médico General | B12: =SUMIFS(NOMINA!$E:$E,NOMINA!$B:$B,A12,NOMINA!$H:$H,E12) | C12: =VLOOKUP(A12,CAPACIDAD!$A:$E,5,FALSE) | D12: =IF(C12>0,B12/C12,0) | E12: Sede Centro - Cali
A13: Enfermero Especializado | B13: =SUMIFS(NOMINA!$E:$E,NOMINA!$B:$B,A13,NOMINA!$H:$H,E13) | C13: =VLOOKUP(A13,CAPACIDAD!$A:$E,5,FALSE) | D13: =IF(C13>0,B13/C13,0) | E13: Sede Norte - Bogotá
A14: Enfermero Especializado | B14: =SUMIFS(NOMINA!$E:$E,NOMINA!$B:$B,A14,NOMINA!$H:$H,E14) | C14: =VLOOKUP(A14,CAPACIDAD!$A:$E,5,FALSE) | D14: =IF(C14>0,B14/C14,0) | E14: Sede Sur - Medellín
A15: Enfermero Especializado | B15: =SUMIFS(NOMINA!$E:$E,NOMINA!$B:$B,A15,NOMINA!$H:$H,E15) | C15: =VLOOKUP(A15,CAPACIDAD!$A:$E,5,FALSE) | D15: =IF(C15>0,B15/C15,0) | E15: Sede Centro - Cali
... A24: Auxiliar de Enfermería | B24: =SUMIFS(NOMINA!$E:$E,NOMINA!$B:$B,A24,NOMINA!$H:$H,E24) | C24: =VLOOKUP(A24,CAPACIDAD!$A:$E,5,FALSE) | D24: =IF(C24>0,B24/C24,0) | E24: Sede Centro - Cali

Sheet SERVICIOS
A1: CATÁLOGO DE SERVICIOS
A3: Código | B3: Nombre del Servicio | C3: Categoría | D3: Complejidad | E3: Requiere Insumos | F3: Estado
A4: SV001 | B4: Ecocardiograma Transtorácico | C4: Diagnóstico No Invasivo | D4: Baja | E4: No | F4: Activo
A5: SV002 | B5: Holter 24 Horas | C5: Diagnóstico No Invasivo | D5: Baja | E5: No | F5: Activo
A6: SV003 | B6: Holter 48 Horas | C6: Diagnóstico No Invasivo | D6: Baja | E6: No | F6: Activo
A7: SV004 | B7: Electrocardiograma | C7: Diagnóstico No Invasivo | D7: Baja | E7: No | F7: Activo
A8: SV005 | B8: MAPA 24 Horas | C8: Diagnóstico No Invasivo | D8: Baja | E8: No | F8: Activo
A9: SV006 | B9: Ecocardiograma Doppler | C9: Diagnóstico No Invasivo | D9: Baja | E9: No | F9: Activo
A10: SV007 | B10: Prueba de Esfuerzo | C10: Diagnóstico Funcional | D10: Media | E10: No | F10: Activo
A11: SV008 | B11: Ecocardiograma de Estrés | C11: Diagnóstico Funcional | D11: Media | E11: No | F11: Activo
A12: SV009 | B12: Tilt Test | C12: Diagnóstico Funcional | D12: Media | E12: No | F12: Activo
A13: SV010 | B13: Ecocardiograma Transesofágico | C13: Diagnóstico Invasivo | D13: Media-Alta | E13: Sí | F13: Activo
A14: SV011 | B14: Estudio Electrofisiológico | C14: Diagnóstico Invasivo | D14: Media-Alta | E14: Sí | F14: Activo
... A23: SV020 | B23: Cierre de CIA | C23: Terapéutico | D23: Alta | E23: Sí | F23: Activo

Sheet ECUACIONES_TIEMPO
A1: ECUACIONES DE TIEMPO TDABC
A2: Núcleo del modelo: Cada servicio consume tiempo de diferentes grupos ocupacionales
A3: FACTOR DE COMPLEJIDAD: Ajusta el tiempo según dificultad del caso. 1.0=normal, 1.2-1.5=complejo, 2.0+=muy complejo. Es AJUSTABLE según su realidad.
A5: Código Servicio | B5: Nombre Servicio | C5: Grupo Ocupacional | D5: Minutos Requeridos | E5: Factor Complejidad | F5: Minutos Ajustados
A6: SV001 | B6: Ecocardiograma Transtorácico | C6: Cardiólogo Especialista | D6: 15 | E6: 1 | F6: =D6*E6
A7: SV001 | B7: Ecocardiograma Transtorácico | C7: Técnico Radiólogo | D7: 20 | E7: 1 | F7: =D7*E7
A8: SV001 | B8: Ecocardiograma Transtorácico | C8: Auxiliar de Enfermería | D8: 10 | E8: 1 | F8: =D8*E8
A9: SV002 | B9: Ecocardiograma Transesofágico | C9: Cardiólogo Especialista | D9: 30 | E9: 1.2 | F9: =D9*E9
A10: SV002 | B10: Ecocardiograma Transesofágico | C10: Enfermero Especializado | D10: 25 | E10: 1 | F10: =D10*E10
A11: SV002 | B11: Ecocardiograma Transesofágico | C11: Auxiliar de Enfermería | D11: 15 | E11: 1 | F11: =D11*E11
A12: SV003 | B12: Holter 24 Horas | C12: Cardiólogo General | D12: 20 | E12: 1 | F12: =D12*E12
A13: SV003 | B13: Holter 24 Horas | C13: Técnico Radiólogo | D13: 30 | E13: 1 | F13: =D13*E13
A14: SV003 | B14: Holter 24 Horas | C14: Auxiliar de Enfermería | D14: 15 | E14: 1 | F14: =D14*E14
A15: SV004 | B15: Holter 48 Horas | C15: Cardiólogo General | D15: 25 | E15: 1.1 | F15: =D15*E15
A16: SV004 | B16: Holter 48 Horas | C16: Técnico Radiólogo | D16: 35 | E16: 1 | F16: =D16*E16
A17: SV004 | B17: Holter 48 Horas | C17: Auxiliar de Enfermería | D17: 20 | E17: 1 | F17: =D17*E17
... A68: SV020 | B68: Biopsia Endomiocárdica | C68: Auxiliar de Enfermería | D68: 30 | E68: 1 | F68: =D68*E68

Sheet INSUMOS
A1: INSUMOS DIRECTOS POR SERVICIO
A3: Código Servicio | B3: Nombre Servicio | C3: Tipo Insumo | D3: Cantidad | E3: Costo Unitario | F3: Costo Total Insumo
A4: SV002 | B4: Ecocardiograma Transesofágico | C4: Gel conductor | D4: 1 | E4: 5000 | F4: =D4*E4
A5: SV002 | B5: Ecocardiograma Transesofágico | C5: Sonda transesofágica (uso) | D5: 1 | E5: 80000 | F5: =D5*E5
A6: SV002 | B6: Ecocardiograma Transesofágico | C6: Material descartable | D6: 1 | E6: 15000 | F6: =D6*E6
A7: SV011 | B7: Estudio Electrofisiológico | C7: Catéter diagnóstico | D7: 2 | E7: 450000 | F7: =D7*E7
A8: SV011 | B8: Estudio Electrofisiológico | C8: Electrodos | D8: 6 | E8: 25000 | F8: =D8*E8
A9: SV011 | B9: Estudio Electrofisiológico | C9: Material quirúrgico | D9: 1 | E9: 120000 | F9: =D9*E9
A10: SV012 | B10: Cardioversión Eléctrica | C10: Electrodos adhesivos | D10: 2 | E10: 35000 | F10: =D10*E10
A11: SV012 | B11: Cardioversión Eléctrica | C11: Medicamentos sedación | D11: 1 | E11: 80000 | F11: =D11*E11
A12: SV012 | B12: Cardioversión Eléctrica | C12: Material descartable | D12: 1 | E12: 20000 | F12: =D12*E12
A13: SV013 | B13: Implante Marcapasos | C13: Marcapasos (dispositivo) | D13: 1 | E13: 8500000 | F13: =D13*E13
A14: SV013 | B14: Implante Marcapasos | C14: Cables de estimulación | D14: 2 | E14: 650000 | F14: =D14*E14
A15: SV013 | B15: Implante Marcapasos | C15: Material quirúrgico | D15: 1 | E15: 180000 | F15: =D15*E15
... A47: SV020 | B47: Biopsia Endomiocárdica | C47: Material descartable | D47: 1 | E47: 120000 | F47: =D47*E47

Sheet PRODUCCION
A1: PRODUCCIÓN MENSUAL Y FACTURACIÓN
A3: Código | B3: Servicio | C3: Sede | D3: Aseguradora | E3: Cantidad | F3: Valor Facturado Promedio | G3: Total Facturado
A4: SV001 | B4: Ecocardiograma Transtorácico | C4: Sede Norte - Bogotá | D4: SURA | E4: 37 | F4: 162195 | G4: =E4*F4
A5: SV001 | B5: Ecocardiograma Transtorácico | C5: Sede Norte - Bogotá | D5: Sanitas | E5: 25 | F5: 227904 | G5: =E5*F5
A6: SV001 | B6: Ecocardiograma Transtorácico | C6: Sede Norte - Bogotá | D6: Compensar | E6: 22 | F6: 159730 | G6: =E6*F6
A7: SV001 | B7: Ecocardiograma Transtorácico | C7: Sede Norte - Bogotá | D7: Salud Total | E7: 30 | F7: 182825 | G7: =E7*F7
A8: SV001 | B8: Ecocardiograma Transtorácico | C8: Sede Norte - Bogotá | D8: Nueva EPS | E8: 28 | F8: 210394 | G8: =E8*F8
A9: SV001 | B9: Ecocardiograma Transtorácico | C9: Sede Sur - Medellín | D9: SURA | E9: 17 | F9: 316216 | G9: =E9*F9
A10: SV001 | B10: Ecocardiograma Transtorácico | C10: Sede Sur - Medellín | D10: Sanitas | E10: 28 | F10: 162397 | G10: =E10*F10
A11: SV001 | B11: Ecocardiograma Transtorácico | C11: Sede Sur - Medellín | D11: Compensar | E11: 32 | F11: 304869 | G11: =E11*F11
A12: SV001 | B12: Ecocardiograma Transtorácico | C12: Sede Sur - Medellín | D12: Salud Total | E12: 34 | F12: 340006 | G12: =E12*F12
A13: SV001 | B13: Ecocardiograma Transtorácico | C13: Sede Sur - Medellín | D13: Nueva EPS | E13: 35 | F13: 317484 | G13: =E13*F13
A14: SV001 | B14: Ecocardiograma Transtorácico | C14: Sede Centro - Cali | D14: SURA | E14: 22 | F14: 199854 | G14: =E14*F14
A15: SV001 | B15: Ecocardiograma Transtorácico | C15: Sede Centro - Cali | D15: Sanitas | E15: 24 | F15: 312267 | G15: =E15*F15
... A303: SV020 | B303: Biopsia Endomiocárdica | C303: Sede Centro - Cali | D303: Nueva EPS | E303: 3 | F303: 1888093 | G303: =E303*F303
B304: TOTAL FACTURACIÓN MENSUAL | E304: =SUM(E4:E303) | G304: =SUM(G4:G303)

Sheet COSTEO_SERVICIOS
A1: HOJA DE COSTEO UNITARIO POR SERVICIO (TDABC)
A2: Nota: Costo CIF calculado con Tasa Real basada en Capacidad Instalada por Sede.
A4: Código | B4: Servicio | C4: Sede | D4: Costo MO Directa | E4: Costo Insumos | F4: Costo CIF (Indirecto) | G4: Costo Unitario Total | H4: Precio Venta Prom. | I4: Margen Unitario | J4: Margen % | K4: Volumen Mes
A5: SV00 | B5: Ecocardiograma Transtorácico | C5: Sede Norte - Bogotá | D5: =SUMIFS(ECUACIONES_TIEMPO!$D:$D,ECUACIONES_TIEMPO!$B:$B,B5)*2200 | E5: =SUMIFS(INSUMOS!$F:$F,INSUMOS!$B:$B,B5) | F5: =SUMIFS(ECUACIONES_TIEMPO!$D:$D,ECUACIONES_TIEMPO!$B:$B,B5)*4055.96 | G5: =D5+E5+F5 | H5: =IFERROR(AVERAGEIFS(PRODUCCION!$F:$F,PRODUCCION!$B:$B,B5,PRODUCCION!$C:$C,C5),0) | I5: =H5-G5 | J5: =IF(H5>0,I5/H5,0) | K5: =SUMIFS(PRODUCCION!$E:$E,PRODUCCION!$B:$B,B5,PRODUCCION!$C:$C,C5)
A6: SV00 | B6: Ecocardiograma Transtorácico | C6: Sede Sur - Medellín | D6: =SUMIFS(ECUACIONES_TIEMPO!$D:$D,ECUACIONES_TIEMPO!$B:$B,B6)*2200 | E6: =SUMIFS(INSUMOS!$F:$F,INSUMOS!$B:$B,B6) | F6: =SUMIFS(ECUACIONES_TIEMPO!$D:$D,ECUACIONES_TIEMPO!$B:$B,B6)*4055.96 | G6: =D6+E6+F6 | H6: =IFERROR(AVERAGEIFS(PRODUCCION!$F:$F,PRODUCCION!$B:$B,B6,PRODUCCION!$C:$C,C6),0) | I6: =H6-G6 | J6: =IF(H6>0,I6/H6,0) | K6: =SUMIFS(PRODUCCION!$E:$E,PRODUCCION!$B:$B,B6,PRODUCCION!$C:$C,C6)
A7: SV00 | B7: Ecocardiograma Transtorácico | C7: Sede Centro - Cali | D7: =SUMIFS(ECUACIONES_TIEMPO!$D:$D,ECUACIONES_TIEMPO!$B:$B,B7)*2200 | E7: =SUMIFS(INSUMOS!$F:$F,INSUMOS!$B:$B,B7) | F7: =SUMIFS(ECUACIONES_TIEMPO!$D:$D,ECUACIONES_TIEMPO!$B:$B,B7)*4055.96 | G7: =D7+E7+F7 | H7: =IFERROR(AVERAGEIFS(PRODUCCION!$F:$F,PRODUCCION!$B:$B,B7,PRODUCCION!$C:$C,C7),0) | I7: =H7-G7 | J7: =IF(H7>0,I7/H7,0) | K7: =SUMIFS(PRODUCCION!$E:$E,PRODUCCION!$B:$B,B7,PRODUCCION!$C:$C,C7)
A8: SV00 | B8: Ecocardiograma Transesofágico | C8: Sede Norte - Bogotá | D8: =SUMIFS(ECUACIONES_TIEMPO!$D:$D,ECUACIONES_TIEMPO!$B:$B,B8)*2200 | E8: =SUMIFS(INSUMOS!$F:$F,INSUMOS!$B:$B,B8) | F8: =SUMIFS(ECUACIONES_TIEMPO!$D:$D,ECUACIONES_TIEMPO!$B:$B,B8)*4055.96 | G8: =D8+E8+F8 | H8: =IFERROR(AVERAGEIFS(PRODUCCION!$F:$F,PRODUCCION!$B:$B,B8,PRODUCCION!$C:$C,C8),0) | I8: =H8-G8 | J8: =IF(H8>0,I8/H8,0) | K8: =SUMIFS(PRODUCCION!$E:$E,PRODUCCION!$B:$B,B8,PRODUCCION!$C:$C,C8)
A9: SV00 | B9: Ecocardiograma Transesofágico | C9: Sede Sur - Medellín | D9: =SUMIFS(ECUACIONES_TIEMPO!$D:$D,ECUACIONES_TIEMPO!$B:$B,B9)*2200 | E9: =SUMIFS(INSUMOS!$F:$F,INSUMOS!$B:$B,B9) | F9: =SUMIFS(ECUACIONES_TIEMPO!$D:$D,ECUACIONES_TIEMPO!$B:$B,B9)*4055.96 | G9: =D9+E9+F9 | H9: =IFERROR(AVERAGEIFS(PRODUCCION!$F:$F,PRODUCCION!$B:$B,B9,PRODUCCION!$C:$C,C9),0) | I9: =H9-G9 | J9: =IF(H9>0,I9/H9,0) | K9: =SUMIFS(PRODUCCION!$E:$E,PRODUCCION!$B:$B,B9,PRODUCCION!$C:$C,C9)
A10: SV00 | B10: Ecocardiograma Transesofágico | C10: Sede Centro - Cali | D10: =SUMIFS(ECUACIONES_TIEMPO!$D:$D,ECUACIONES_TIEMPO!$B:$B,B10)*2200 | E10: =SUMIFS(INSUMOS!$F:$F,INSUMOS!$B:$B,B10) | F10: =SUMIFS(ECUACIONES_TIEMPO!$D:$D,ECUACIONES_TIEMPO!$B:$B,B10)*4055.96 | G10: =D10+E10+F10 | H10: =IFERROR(AVERAGEIFS(PRODUCCION!$F:$F,PRODUCCION!$B:$B,B10,PRODUCCION!$C:$C,C10),0) | I10: =H10-G10 | J10: =IF(H10>0,I10/H10,0) | K10: =SUMIFS(PRODUCCION!$E:$E,PRODUCCION!$B:$B,B10,PRODUCCION!$C:$C,C10)
A11: SV00 | B11: Holter 24 Horas | C11: Sede Norte - Bogotá | D11: =SUMIFS(ECUACIONES_TIEMPO!$D:$D,ECUACIONES_TIEMPO!$B:$B,B11)*2200 | E11: =SUMIFS(INSUMOS!$F:$F,INSUMOS!$B:$B,B11) | F11: =SUMIFS(ECUACIONES_TIEMPO!$D:$D,ECUACIONES_TIEMPO!$B:$B,B11)*4055.96 | G11: =D11+E11+F11 | H11: =IFERROR(AVERAGEIFS(PRODUCCION!$F:$F,PRODUCCION!$B:$B,B11,PRODUCCION!$C:$C,C11),0) | I11: =H11-G11 | J11: =IF(H11>0,I11/H11,0) | K11: =SUMIFS(PRODUCCION!$E:$E,PRODUCCION!$B:$B,B11,PRODUCCION!$C:$C,C11)
A12: SV00 | B12: Holter 24 Horas | C12: Sede Sur - Medellín | D12: =SUMIFS(ECUACIONES_TIEMPO!$D:$D,ECUACIONES_TIEMPO!$B:$B,B12)*2200 | E12: =SUMIFS(INSUMOS!$F:$F,INSUMOS!$B:$B,B12) | F12: =SUMIFS(ECUACIONES_TIEMPO!$D:$D,ECUACIONES_TIEMPO!$B:$B,B12)*4055.96 | G12: =D12+E12+F12 | H12: =IFERROR(AVERAGEIFS(PRODUCCION!$F:$F,PRODUCCION!$B:$B,B12,PRODUCCION!$C:$C,C12),0) | I12: =H12-G12 | J12: =IF(H12>0,I12/H12,0) | K12: =SUMIFS(PRODUCCION!$E:$E,PRODUCCION!$B:$B,B12,PRODUCCION!$C:$C,C12)
A13: SV00 | B13: Holter 24 Horas | C13: Sede Centro - Cali | D13: =SUMIFS(ECUACIONES_TIEMPO!$D:$D,ECUACIONES_TIEMPO!$B:$B,B13)*2200 | E13: =SUMIFS(INSUMOS!$F:$F,INSUMOS!$B:$B,B13) | F13: =SUMIFS(ECUACIONES_TIEMPO!$D:$D,ECUACIONES_TIEMPO!$B:$B,B13)*4055.96 | G13: =D13+E13+F13 | H13: =IFERROR(AVERAGEIFS(PRODUCCION!$F:$F,PRODUCCION!$B:$B,B13,PRODUCCION!$C:$C,C13),0) | I13: =H13-G13 | J13: =IF(H13>0,I13/H13,0) | K13: =SUMIFS(PRODUCCION!$E:$E,PRODUCCION!$B:$B,B13,PRODUCCION!$C:$C,C13)
A14: SV00 | B14: Holter 48 Horas | C14: Sede Norte - Bogotá | D14: =SUMIFS(ECUACIONES_TIEMPO!$D:$D,ECUACIONES_TIEMPO!$B:$B,B14)*2200 | E14: =SUMIFS(INSUMOS!$F:$F,INSUMOS!$B:$B,B14) | F14: =SUMIFS(ECUACIONES_TIEMPO!$D:$D,ECUACIONES_TIEMPO!$B:$B,B14)*4055.96 | G14: =D14+E14+F14 | H14: =IFERROR(AVERAGEIFS(PRODUCCION!$F:$F,PRODUCCION!$B:$B,B14,PRODUCCION!$C:$C,C14),0) | I14: =H14-G14 | J14: =IF(H14>0,I14/H14,0) | K14: =SUMIFS(PRODUCCION!$E:$E,PRODUCCION!$B:$B,B14,PRODUCCION!$C:$C,C14)
A15: SV00 | B15: Holter 48 Horas | C15: Sede Sur - Medellín | D15: =SUMIFS(ECUACIONES_TIEMPO!$D:$D,ECUACIONES_TIEMPO!$B:$B,B15)*2200 | E15: =SUMIFS(INSUMOS!$F:$F,INSUMOS!$B:$B,B15) | F15: =SUMIFS(ECUACIONES_TIEMPO!$D:$D,ECUACIONES_TIEMPO!$B:$B,B15)*4055.96 | G15: =D15+E15+F15 | H15: =IFERROR(AVERAGEIFS(PRODUCCION!$F:$F,PRODUCCION!$B:$B,B15,PRODUCCION!$C:$C,C15),0) | I15: =H15-G15 | J15: =IF(H15>0,I15/H15,0) | K15: =SUMIFS(PRODUCCION!$E:$E,PRODUCCION!$B:$B,B15,PRODUCCION!$C:$C,C15)
A16: SV00 | B16: Holter 48 Horas | C16: Sede Centro - Cali | D16: =SUMIFS(ECUACIONES_TIEMPO!$D:$D,ECUACIONES_TIEMPO!$B:$B,B16)*2200 | E16: =SUMIFS(INSUMOS!$F:$F,INSUMOS!$B:$B,B16) | F16: =SUMIFS(ECUACIONES_TIEMPO!$D:$D,ECUACIONES_TIEMPO!$B:$B,B16)*4055.96 | G16: =D16+E16+F16 | H16: =IFERROR(AVERAGEIFS(PRODUCCION!$F:$F,PRODUCCION!$B:$B,B16,PRODUCCION!$C:$C,C16),0) | I16: =H16-G16 | J16: =IF(H16>0,I16/H16,0) | K16: =SUMIFS(PRODUCCION!$E:$E,PRODUCCION!$B:$B,B16,PRODUCCION!$C:$C,C16)
... A64: SV00 | B64: Biopsia Endomiocárdica | C64: Sede Centro - Cali | D64: =SUMIFS(ECUACIONES_TIEMPO!$D:$D,ECUACIONES_TIEMPO!$B:$B,B64)*2200 | E64: =SUMIFS(INSUMOS!$F:$F,INSUMOS!$B:$B,B64) | F64: =SUMIFS(ECUACIONES_TIEMPO!$D:$D,ECUACIONES_TIEMPO!$B:$B,B64)*4055.96 | G64: =D64+E64+F64 | H64: =IFERROR(AVERAGEIFS(PRODUCCION!$F:$F,PRODUCCION!$B:$B,B64,PRODUCCION!$C:$C,C64),0) | I64: =H64-G64 | J64: =IF(H64>0,I64/H64,0) | K64: =SUMIFS(PRODUCCION!$E:$E,PRODUCCION!$B:$B,B64,PRODUCCION!$C:$C,C64)

Sheet COSTOS_INDIRECTOS
A1: AUXILIAR DE COSTOS DE PRODUCCIÓN (CLASE 7)
A2: Consolidación de Costos Directos e Indirectos (P.U.C.)
A4: Código Cuenta | B4: Concepto | C4: Sede | D4: Valor Mensual | E4: Criterio Distribución | F4: Tipo Gasto
A5: 7105 | B5: COSTO MATERIA PRIMA (INSUMOS) | C5: Sede Norte - Bogotá | D5: =SUMPRODUCT((COSTEO_SERVICIOS!$C$5:$C$500="Sede Norte - Bogotá")*(COSTEO_SERVICIOS!$E$5:$E$500)*(COSTEO_SERVICIOS!$K$5:$K$500)) | E5: Consumo Real (Volumen) | F5: Variable
A6: 7205 | B6: COSTO MANO DE OBRA DIRECTA | C6: Sede Norte - Bogotá | D6: =SUMIFS(NOMINA!$G:$G,NOMINA!$H:$H,"Sede Norte - Bogotá") | E6: Nómina Directa | F6: Fijo
A7: 7105 | B7: COSTO MATERIA PRIMA (INSUMOS) | C7: Sede Sur - Medellín | D7: =SUMPRODUCT((COSTEO_SERVICIOS!$C$5:$C$500="Sede Sur - Medellín")*(COSTEO_SERVICIOS!$E$5:$E$500)*(COSTEO_SERVICIOS!$K$5:$K$500)) | E7: Consumo Real (Volumen) | F7: Variable
A8: 7205 | B8: COSTO MANO DE OBRA DIRECTA | C8: Sede Sur - Medellín | D8: =SUMIFS(NOMINA!$G:$G,NOMINA!$H:$H,"Sede Sur - Medellín") | E8: Nómina Directa | F8: Fijo
A9: 7105 | B9: COSTO MATERIA PRIMA (INSUMOS) | C9: Sede Centro - Cali | D9: =SUMPRODUCT((COSTEO_SERVICIOS!$C$5:$C$500="Sede Centro - Cali")*(COSTEO_SERVICIOS!$E$5:$E$500)*(COSTEO_SERVICIOS!$K$5:$K$500)) | E9: Consumo Real (Volumen) | F9: Variable
A10: 7205 | B10: COSTO MANO DE OBRA DIRECTA | C10: Sede Centro - Cali | D10: =SUMIFS(NOMINA!$G:$G,NOMINA!$H:$H,"Sede Centro - Cali") | E10: Nómina Directa | F10: Fijo
A11: 7305 | B11: Arrendamiento | C11: Sede Norte - Bogotá | D11: 66666667 | E11: Capacidad Instalada (Minutos) | F11: Fijo
A12: 7305 | B12: Arrendamiento | C12: Sede Sur - Medellín | D12: 50000000 | E12: Capacidad Instalada (Minutos) | F12: Fijo
A13: 7305 | B13: Arrendamiento | C13: Sede Centro - Cali | D13: 33333333 | E13: Capacidad Instalada (Minutos) | F13: Fijo
A14: 7310 | B14: Depreciación Equipos | C14: Sede Norte - Bogotá | D14: 37777778 | E14: Capacidad Instalada (Minutos) | F14: Fijo
A15: 7310 | B15: Depreciación Equipos | C15: Sede Sur - Medellín | D15: 28333333 | E15: Capacidad Instalada (Minutos) | F15: Fijo
A16: 7310 | B16: Depreciación Equipos | C16: Sede Centro - Cali | D16: 18888889 | E16: Capacidad Instalada (Minutos) | F16: Fijo
A17: 7315 | B17: Mantenimiento | C17: Sede Norte - Bogotá | D17: 20000000 | E17: Capacidad Instalada (Minutos) | F17: Fijo
A18: 7315 | B18: Mantenimiento | C18: Sede Sur - Medellín | D18: 15000000 | E18: Capacidad Instalada (Minutos) | F18: Fijo
A19: 7315 | B19: Mantenimiento | C19: Sede Centro - Cali | D19: 10000000 | E19: Capacidad Instalada (Minutos) | F19: Fijo
A20: 7320 | B20: Servicios Públicos | C20: Sede Norte - Bogotá | D20: 15555556 | E20: Capacidad Instalada (Minutos) | F20: Fijo
A21: 7320 | B21: Servicios Públicos | C21: Sede Sur - Medellín | D21: 11666667 | E21: Capacidad Instalada (Minutos) | F21: Fijo
A22: 7320 | B22: Servicios Públicos | C22: Sede Centro - Cali | D22: 7777777.8 | E22: Capacidad Instalada (Minutos) | F22: Fijo
... A37: 7390 | B37: Otros | C37: Sede Centro - Cali | D37: 3333333.3 | E37: Capacidad Instalada (Minutos) | F37: Fijo

Sheet RESUMEN_EJECUTIVO
A1: CardioCentro Diagnóstico Integral S.A.S.
A2: RESUMEN EJECUTIVO - ANÁLISIS DE RENTABILIDAD (Enero)
A3: Período: February 2026
A5: INDICADORES GLOBALES DE RESULTADOS
A6: Indicador | B6: Valor
A7: Ingresos Operacionales (Facturación) | B7: =SUM(TablaProduccion[Total Facturado])
A8: Total Costos Asignados (TDABC) | B8: =SUM(TablaCosteo[Costo Unitario Total]*TablaCosteo[Volumen Mes])
A9: - Costo Personal Directo | B9: =SUM(TablaCosteo[Costo MO Directa]*TablaCosteo[Volumen Mes])
A10: - Costo Insumos | B10: =SUM(TablaCosteo[Costo Insumos]*TablaCosteo[Volumen Mes])
A11: - Costos Indirectos (CIF) | B11: =SUM(TablaCosteo[Costo CIF (Indirecto)]*TablaCosteo[Volumen Mes])
A12: Utilidad Operacional (Estimada) | B12: =B7-B8
A13: Margen Operacional % | B13: =IF(B7>0,B12/B7,0)
A14: Total Servicios Prestados | B14: =SUM(TablaProduccion[Cantidad])
A15: MARGEN OPERATIVO | B15: =B7-B8
A16: MARGEN OPERATIVO % | B16: =IF(B7>0,B13/B7,0)
A19: CONCILIACIÓN DE COSTOS (CONTABLE VS DISTRIBUIDO)
A20: Concepto (Fuente: COSTOS_INDIRECTOS) | B20: Costo Contable (Gastado) | C20: Costo Asignado (TDABC)
A21: Materia Prima / Insumos (71) | B21: =SUMIFS(TablaIndirectos[Valor Mensual],TablaIndirectos[Código Cuenta],"71*") | C21: =SUMPRODUCT(TablaCosteo[Costo Insumos],TablaCosteo[Volumen Mes])
A22: Mano de Obra Directa (72) | B22: =SUMIFS(TablaIndirectos[Valor Mensual],TablaIndirectos[Código Cuenta],"72*") | C22: =SUMPRODUCT(TablaCosteo[Costo MO Directa],TablaCosteo[Volumen Mes])
A23: Costos Indirectos CIF (73) | B23: =SUMIFS(TablaIndirectos[Valor Mensual],TablaIndirectos[Código Cuenta],"73*") | C23: =SUMPRODUCT(TablaCosteo[Costo CIF (Indirecto)],TablaCosteo[Volumen Mes])
A24: DIFERENCIA (CAPACIDAD OCIOSA) | B24: =SUM(B21:B23)-SUM(C21:C23)
A25: NOTA IMPORTANTE: La Diferencia en '73' corresponde a la CAPACIDAD OCIOSA DE INFRAESTRUCTURA. > Valores Positivos (+) indican que se está pagando por una sede que NO se usa completamente (Pérdida por Vacío). > Valores Negativos (-) indican Sobre-ejecución (se trabajó más de la capacidad teórica/turnos extra).
A28: RENTABILIDAD POR SERVICIO (TODOS)
A29: Servicio | B29: Costo Total | C29: Facturación Total | D29: Margen Total | E29: Margen %
A30: Ecocardiograma Transtorácico | B30: =SUMPRODUCT((TablaCosteo[Servicio]=A30)*(TablaCosteo[Costo Unitario Total])*(TablaCosteo[Volumen Mes])) | C30: =SUMIFS(TablaProduccion[Total Facturado],TablaProduccion[Servicio],A30) | D30: =C30-B30 | E30: =IF(C30>0,D30/C30,0)
A31: Ecocardiograma Transesofágico | B31: =SUMPRODUCT((TablaCosteo[Servicio]=A31)*(TablaCosteo[Costo Unitario Total])*(TablaCosteo[Volumen Mes])) | C31: =SUMIFS(TablaProduccion[Total Facturado],TablaProduccion[Servicio],A31) | D31: =C31-B31 | E31: =IF(C31>0,D31/C31,0)
A32: Holter 24 Horas | B32: =SUMPRODUCT((TablaCosteo[Servicio]=A32)*(TablaCosteo[Costo Unitario Total])*(TablaCosteo[Volumen Mes])) | C32: =SUMIFS(TablaProduccion[Total Facturado],TablaProduccion[Servicio],A32) | D32: =C32-B32 | E32: =IF(C32>0,D32/C32,0)
A33: Holter 48 Horas | B33: =SUMPRODUCT((TablaCosteo[Servicio]=A33)*(TablaCosteo[Costo Unitario Total])*(TablaCosteo[Volumen Mes])) | C33: =SUMIFS(TablaProduccion[Total Facturado],TablaProduccion[Servicio],A33) | D33: =C33-B33 | E33: =IF(C33>0,D33/C33,0)
A34: Prueba de Esfuerzo | B34: =SUMPRODUCT((TablaCosteo[Servicio]=A34)*(TablaCosteo[Costo Unitario Total])*(TablaCosteo[Volumen Mes])) | C34: =SUMIFS(TablaProduccion[Total Facturado],TablaProduccion[Servicio],A34) | D34: =C34-B34 | E34: =IF(C34>0,D34/C34,0)
A35: Electrocardiograma | B35: =SUMPRODUCT((TablaCosteo[Servicio]=A35)*(TablaCosteo[Costo Unitario Total])*(TablaCosteo[Volumen Mes])) | C35: =SUMIFS(TablaProduccion[Total Facturado],TablaProduccion[Servicio],A35) | D35: =C35-B35 | E35: =IF(C35>0,D35/C35,0)
A36: MAPA 24 Horas | B36: =SUMPRODUCT((TablaCosteo[Servicio]=A36)*(TablaCosteo[Costo Unitario Total])*(TablaCosteo[Volumen Mes])) | C36: =SUMIFS(TablaProduccion[Total Facturado],TablaProduccion[Servicio],A36) | D36: =C36-B36 | E36: =IF(C36>0,D36/C36,0)
A37: Ecocardiograma Doppler | B37: =SUMPRODUCT((TablaCosteo[Servicio]=A37)*(TablaCosteo[Costo Unitario Total])*(TablaCosteo[Volumen Mes])) | C37: =SUMIFS(TablaProduccion[Total Facturado],TablaProduccion[Servicio],A37) | D37: =C37-B37 | E37: =IF(C37>0,D37/C37,0)
A38: Ecocardiograma de Estrés | B38: =SUMPRODUCT((TablaCosteo[Servicio]=A38)*(TablaCosteo[Costo Unitario Total])*(TablaCosteo[Volumen Mes])) | C38: =SUMIFS(TablaProduccion[Total Facturado],TablaProduccion[Servicio],A38) | D38: =C38-B38 | E38: =IF(C38>0,D38/C38,0)
A39: Tilt Test | B39: =SUMPRODUCT((TablaCosteo[Servicio]=A39)*(TablaCosteo[Costo Unitario Total])*(TablaCosteo[Volumen Mes])) | C39: =SUMIFS(TablaProduccion[Total Facturado],TablaProduccion[Servicio],A39) | D39: =C39-B39 | E39: =IF(C39>0,D39/C39,0)
A40: Estudio Electrofisiológico | B40: =SUMPRODUCT((TablaCosteo[Servicio]=A40)*(TablaCosteo[Costo Unitario Total])*(TablaCosteo[Volumen Mes])) | C40: =SUMIFS(TablaProduccion[Total Facturado],TablaProduccion[Servicio],A40) | D40: =C40-B40 | E40: =IF(C40>0,D40/C40,0)
A41: Cardioversión Eléctrica | B41: =SUMPRODUCT((TablaCosteo[Servicio]=A41)*(TablaCosteo[Costo Unitario Total])*(TablaCosteo[Volumen Mes])) | C41: =SUMIFS(TablaProduccion[Total Facturado],TablaProduccion[Servicio],A41) | D41: =C41-B41 | E41: =IF(C41>0,D41/C41,0)
... A49: Biopsia Endomiocárdica | B49: =SUMPRODUCT((TablaCosteo[Servicio]=A49)*(TablaCosteo[Costo Unitario Total])*(TablaCosteo[Volumen Mes])) | C49: =SUMIFS(TablaProduccion[Total Facturado],TablaProduccion[Servicio],A49) | D49: =C49-B49 | E49: =IF(C49>0,D49/C49,0)
A52: ANÁLISIS POR SEDE
A53: Sede | B53: Facturación | C53: Costos | D53: Margen | E53: Margen %
A54: Sede Norte - Bogotá | B54: =SUMIFS(TablaProduccion[Total Facturado],TablaProduccion[Sede],A54) | C54: =SUMPRODUCT((TablaCosteo[Sede]=A54)*(TablaCosteo[Costo Unitario Total])*(TablaCosteo[Volumen Mes])) | D54: =B54-C54 | E54: =IF(B54>0,D54/B54,0)
...
